
/Users/enochoforiantwi/Library/Python/3.9/lib/python/site-packages/urllib3/__init__.py:35: NotOpenSSLWarning: urllib3 v2 only supports OpenSSL 1.1.1+, currently the 'ssl' module is compiled with 'LibreSSL 2.8.3'. See: https://github.com/urllib3/urllib3/issues/3020
  warnings.warn(
Enter the location: new york
Traceback (most recent call last):
  File "/Users/enochoforiantwi/Library/Python/3.9/lib/python/site-packages/geopy/geocoders/base.py", line 368, in _call_geocoder
    result = self.adapter.get_json(url, timeout=timeout, headers=req_headers)
  File "/Users/enochoforiantwi/Library/Python/3.9/lib/python/site-packages/geopy/adapters.py", line 472, in get_json
    resp = self._request(url, timeout=timeout, headers=headers)
  File "/Users/enochoforiantwi/Library/Python/3.9/lib/python/site-packages/geopy/adapters.py", line 500, in _request
    raise AdapterHTTPError(
geopy.adapters.AdapterHTTPError: Non-successful status code 403

The above exception was the direct cause of the following exception:

Traceback (most recent call last):
  File "/Users/enochoforiantwi/projects/weather-app/weather_microservice/app.py", line 80, in <module>
    coordinates = get_coordinates(location)
  File "/Users/enochoforiantwi/projects/weather-app/weather_microservice/app.py", line 15, in get_coordinates
    coordinates = geolocator.geocode(location)
  File "/Users/enochoforiantwi/Library/Python/3.9/lib/python/site-packages/geopy/geocoders/nominatim.py", line 297, in geocode
    return self._call_geocoder(url, callback, timeout=timeout)
  File "/Users/enochoforiantwi/Library/Python/3.9/lib/python/site-packages/geopy/geocoders/base.py", line 388, in _call_geocoder
    res = self._adapter_error_handler(error)
  File "/Users/enochoforiantwi/Library/Python/3.9/lib/python/site-packages/geopy/geocoders/base.py", line 411, in _adapter_error_handler
    raise exc_cls(str(error)) from error
geopy.exc.GeocoderInsufficientPrivileges: Non-successful status code 403


Enter the location: new york
Traceback (most recent call last):
  File "/Users/enochoforiantwi/Library/Python/3.9/lib/python/site-packages/geopy/geocoders/base.py", line 368, in _call_geocoder
    result = self.adapter.get_json(url, timeout=timeout, headers=req_headers)
  File "/Users/enochoforiantwi/Library/Python/3.9/lib/python/site-packages/geopy/adapters.py", line 472, in get_json
    resp = self._request(url, timeout=timeout, headers=headers)
  File "/Users/enochoforiantwi/Library/Python/3.9/lib/python/site-packages/geopy/adapters.py", line 500, in _request
    raise AdapterHTTPError(
geopy.adapters.AdapterHTTPError: Non-successful status code 403

The above exception was the direct cause of the following exception:

Traceback (most recent call last):
  File "/Users/enochoforiantwi/projects/weather-app/weather_microservice/app.py", line 80, in <module>
    coordinates = get_coordinates(location)
  File "/Users/enochoforiantwi/projects/weather-app/weather_microservice/app.py", line 15, in get_coordinates
    coordinates = geolocator.geocode(location)
  File "/Users/enochoforiantwi/Library/Python/3.9/lib/python/site-packages/geopy/geocoders/nominatim.py", line 297, in geocode
    return self._call_geocoder(url, callback, timeout=timeout)
  File "/Users/enochoforiantwi/Library/Python/3.9/lib/python/site-packages/geopy/geocoders/base.py", line 388, in _call_geocoder
    res = self._adapter_error_handler(error)
  File "/Users/enochoforiantwi/Library/Python/3.9/lib/python/site-packages/geopy/geocoders/base.py", line 411, in _adapter_error_handler
    raise exc_cls(str(error)) from error
geopy.exc.GeocoderInsufficientPrivileges: Non-successful status code 403
